Exception in thread Thread-4 (THR_PLC):
Traceback (most recent call last):
  File "/usr/lib/python3.13/threading.py", line 1043, in _bootstrap_inner
    self.run()
    ~~~~~~~~^^
  File "/usr/lib/python3.13/threading.py", line 994, in run
    self._target(*self._args, **self._kwargs)
    ~~~~~~~~~~~~^^^^^^^^^^^^^^^^^^^^^^^^^^^^^
  File "/home/w/readIO4.py", line 485, in THR_PLC
    sock = reconnect(plc_ip, PLC_PORT, device_num, plc_name)
  File "/home/w/readIO4.py", line 447, in reconnect
    return reconnect(plc_ip, plc_port, device_num, plc_name)
  File "/home/w/readIO4.py", line 447, in reconnect
    return reconnect(plc_ip, plc_port, device_num, plc_name)
  File "/home/w/readIO4.py", line 447, in reconnect
    return reconnect(plc_ip, plc_port, device_num, plc_name)
  [Previous line repeated 981 more times]
  File "/home/w/readIO4.py", line 435, in reconnect
    logger.info(f"{plc_name}: Reconnecting (attempt {attempt}/{max_retries})")
    ~~~~~~~~~~~^^^^^^^^^^^^^^^^^^^^^^^^^^^^^^^^^^^^^^^^^^^^^^^^^^^^^^^^^^^^^^^
  File "/usr/lib/python3.13/logging/__init__.py", line 1520, in info
    self._log(INFO, msg, args, **kwargs)
    ~~~~~~~~~^^^^^^^^^^^^^^^^^^^^^^^^^^^
  File "/usr/lib/python3.13/logging/__init__.py", line 1665, in _log
    self.handle(record)
    ~~~~~~~~~~~^^^^^^^^
  File "/usr/lib/python3.13/logging/__init__.py", line 1681, in handle
    self.callHandlers(record)
    ~~~~~~~~~~~~~~~~~^^^^^^^^
  File "/usr/lib/python3.13/logging/__init__.py", line 1737, in callHandlers
    hdlr.handle(record)
    ~~~~~~~~~~~^^^^^^^^
  File "/usr/lib/python3.13/logging/__init__.py", line 1027, in handle
    self.emit(record)
    ~~~~~~~~~^^^^^^^^
  File "/usr/lib/python3.13/logging/__init__.py", line 1265, in emit
    StreamHandler.emit(self, record)
    ~~~~~~~~~~~~~~~~~~^^^^^^^^^^^^^^
  File "/usr/lib/python3.13/logging/__init__.py", line 1151, in emit
    msg = self.format(record)
  File "/usr/lib/python3.13/logging/__init__.py", line 999, in format
    return fmt.format(record)
           ~~~~~~~~~~^^^^^^^^
  File "/usr/lib/python3.13/logging/__init__.py", line 715, in format
    s = self.formatMessage(record)
  File "/usr/lib/python3.13/logging/__init__.py", line 684, in formatMessage
    return self._style.format(record)
           ~~~~~~~~~~~~~~~~~~^^^^^^^^
  File "/usr/lib/python3.13/logging/__init__.py", line 472, in format
    return self._format(record)
           ~~~~~~~~~~~~^^^^^^^^
RecursionError: maximum recursion depth exceeded
